2024-05-17 15:21:18,346 INFO    MainThread:20952 [wandb_setup.py:_flush():76] Current SDK version is 0.16.4
2024-05-17 15:21:18,362 INFO    MainThread:20952 [wandb_setup.py:_flush():76] Configure stats pid to 20952
2024-05-17 15:21:18,362 INFO    MainThread:20952 [wandb_setup.py:_flush():76] Loading settings from C:\Users\Federico\.config\wandb\settings
2024-05-17 15:21:18,362 INFO    MainThread:20952 [wandb_setup.py:_flush():76] Loading settings from c:\Users\Federico\Documents\Parking-lot\wandb\settings
2024-05-17 15:21:18,362 INFO    MainThread:20952 [wandb_setup.py:_flush():76] Loading settings from environment variables: {}
2024-05-17 15:21:18,362 INFO    MainThread:20952 [wandb_setup.py:_flush():76] Applying setup settings: {'_disable_service': False}
2024-05-17 15:21:18,362 INFO    MainThread:20952 [wandb_setup.py:_flush():76] Inferring run settings from compute environment: {'program': '<python with no main file>'}
2024-05-17 15:21:18,362 INFO    MainThread:20952 [wandb_init.py:_log_setup():526] Logging user logs to c:\Users\Federico\Documents\Parking-lot\wandb\run-20240517_152118-7urv2m42\logs\debug.log
2024-05-17 15:21:18,362 INFO    MainThread:20952 [wandb_init.py:_log_setup():527] Logging internal logs to c:\Users\Federico\Documents\Parking-lot\wandb\run-20240517_152118-7urv2m42\logs\debug-internal.log
2024-05-17 15:21:18,362 INFO    MainThread:20952 [wandb_init.py:_jupyter_setup():472] configuring jupyter hooks <wandb.sdk.wandb_init._WandbInit object at 0x00000250221A7190>
2024-05-17 15:21:18,362 INFO    MainThread:20952 [wandb_init.py:init():566] calling init triggers
2024-05-17 15:21:18,362 INFO    MainThread:20952 [wandb_init.py:init():573] wandb.init called with sweep_config: {}
config: {}
2024-05-17 15:21:18,362 INFO    MainThread:20952 [wandb_init.py:init():616] starting backend
2024-05-17 15:21:18,362 INFO    MainThread:20952 [wandb_init.py:init():620] setting up manager
2024-05-17 15:21:18,362 INFO    MainThread:20952 [backend.py:_multiprocessing_setup():105] multiprocessing start_methods=spawn, using: spawn
2024-05-17 15:21:18,385 INFO    MainThread:20952 [wandb_init.py:init():628] backend started and connected
2024-05-17 15:21:18,397 INFO    MainThread:20952 [wandb_run.py:_label_probe_notebook():1295] probe notebook
2024-05-17 15:21:18,397 INFO    MainThread:20952 [wandb_run.py:_label_probe_notebook():1305] Unable to probe notebook: 'NoneType' object has no attribute 'get'
2024-05-17 15:21:18,397 INFO    MainThread:20952 [wandb_init.py:init():720] updated telemetry
2024-05-17 15:21:18,489 INFO    MainThread:20952 [wandb_init.py:init():753] communicating run to backend with 90.0 second timeout
2024-05-17 15:21:19,385 ERROR   MainThread:20952 [wandb_init.py:init():779] encountered error: It appears that you do not have permission to access the requested resource. Please reach out to the project owner to grant you access. If you have the correct permissions, verify that there are no issues with your networking setup.(Error 404: Not Found)
2024-05-17 15:21:19,763 ERROR   MainThread:20952 [wandb_init.py:init():1194] It appears that you do not have permission to access the requested resource. Please reach out to the project owner to grant you access. If you have the correct permissions, verify that there are no issues with your networking setup.(Error 404: Not Found)
Traceback (most recent call last):
  File "c:\Users\Federico\AppData\Local\Programs\Python\Python311\Lib\site-packages\wandb\sdk\wandb_init.py", line 1176, in init
    run = wi.init()
          ^^^^^^^^^
  File "c:\Users\Federico\AppData\Local\Programs\Python\Python311\Lib\site-packages\wandb\sdk\wandb_init.py", line 785, in init
    raise error
wandb.errors.CommError: It appears that you do not have permission to access the requested resource. Please reach out to the project owner to grant you access. If you have the correct permissions, verify that there are no issues with your networking setup.(Error 404: Not Found)
